<robot name="HyQ">
<link name="base_link">
    <visual>
      <geometry>
        <cylinder length="0.01" radius="0.01"/>
      </geometry>
      <material name="blue">
        <color rgba="0 0 .8 1"/>
      </material>
    </visual>
  </link>

<link name="trunk">
    <visual>
	<origin xyz="0 0 0" rpy="0 0 0" />
	<geometry>
	<mesh filename="package://hyq_model/meshes/trunk.dae" scale="1 1 1"/>
	</geometry>
<material name="white">
        <color rgba="1 1 1 1"/>
      </material>
    </visual>
<collision>
  <geometry>
    <mesh filename="package://hyq_model/meshes/trunk_convex.dae" scale="0.001 0.001 0.001"/>
  </geometry>
</collision>
    <inertial>
        <origin xyz="-0.00020  0.00010  0.00110"/>
        <mass value="53.0"/>
        <inertia ixx="1.26" iyy="6.56" izz="6.69" ixy="0.03" ixz="-0.06" iyz="-0.03"/>
    </inertial>
</link>


<link name="LF_hip_assembly">
    <inertial>
        <origin xyz=" 0.01310  0.00010  0.05730"/>
        <mass value="2.482"/>
        <inertia ixx="0.0956126" iyy="0.1012626" izz="6.758E-4" ixy="0.0" ixz="-0.011" iyz="0.0"/>
    </inertial>
 <visual>
<origin xyz="0 0 0" rpy="0 0 0" />
	<geometry>
	<mesh filename="package://hyq_model/meshes/hip.dae" scale="1 1 1"/>
	</geometry>
      <material name="white"/>
    </visual>
<collision>
<origin xyz="0 0 0" rpy="3.141592654 -1.5707964 0" />
  <geometry>
    <mesh filename="package://hyq_model/meshes/hip_convex.dae" scale="0.001 0.001 0.001"/>
  </geometry>
</collision>
</link>

<link name="LF_upper_leg">
    <inertial>
	<origin xyz="0.35  0.02  -0.025" rpy="3.141592654 0 -1.5707964"/> 
        <mass value="2.16"/>
        <inertia ixx="0.004785" iyy="0.076166" izz="0.078576" ixy="0.0071588" ixz="0.0" iyz="0.0"/>
    </inertial>
 <visual> 
<origin xyz="0. 0 0" rpy="0 0 0" />
	<geometry>
	<mesh filename="package://hyq_model/meshes/upper.dae" scale="1 1 1"/>
	</geometry>
      <material name="white"/>
    </visual>
<collision>
  <geometry>
    <mesh filename="package://hyq_model/meshes/upper_convex.dae" scale="0.001 0.001 0.001"/>
  </geometry>
</collision>
</link>

<link name="LF_lower_leg">
    <inertial>
        <origin xyz=" 0.17830  0.00030 -0.00010"/>
        <mass value="1.8717"/>
        <inertia ixx="9.0E-4" iyy="0.0777" izz="0.0775" ixy="-0.0" ixz="-0.0" iyz="0.0"/>
    </inertial>
 <visual>
<origin xyz="0 0 0" rpy="0 0 0" />
	<geometry>
	<mesh filename="package://hyq_model/meshes/lower.dae" scale="1 1 1"/>
	</geometry>
      <material name="white"/>
    </visual>
<collision>
  <geometry>
    <mesh filename="package://hyq_model/meshes/lower_convex.dae" scale="0.001 0.001 0.001"/>
  </geometry>
</collision>
</link>



<link name="RF_hip_assembly">
    <inertial>
        <origin xyz=" 0.01310 -0.00010 -0.05730"/>
        <mass value="2.482"/>
        <inertia ixx="0.0956126" iyy="0.1012626" izz="6.758E-4" ixy="0.0" ixz="0.011" iyz="0.0"/>
    </inertial>
 <visual>
<origin xyz="0 0 0" rpy="3.141592654 0 0" />
	<geometry>
	<mesh filename="package://hyq_model/meshes/hip.dae" scale="1 1 1"/>
	</geometry>
      <material name="white"/>
    </visual>
<collision>
<origin xyz="0 0 0" rpy="0 1.5707964 0" />
  <geometry>
    <mesh filename="package://hyq_model/meshes/hip_convex.dae" scale="0.001 0.001 0.001"/>
  </geometry>
</collision>
</link>

<link name="RF_upper_leg">
    <inertial>
        <origin xyz=" 0.14796 -0.02958  0.00000"/>
        <mass value="2.16"/>
        <inertia ixx="0.004785" iyy="0.076166" izz="0.078576" ixy="0.0071588" ixz="0.0" iyz="0.0"/>
    </inertial>
 <visual> 
<origin xyz="0 0 0" rpy="0 0 0" />
	<geometry>
	<mesh filename="package://hyq_model/meshes/upper.dae" scale="1 1 1"/>
	</geometry>
      <material name="white"/>
    </visual>
<collision>
  <geometry>
    <mesh filename="package://hyq_model/meshes/upper_convex.dae" scale="0.001 0.001 0.001"/>
  </geometry>
</collision>
</link>

<link name="RF_lower_leg">
    <inertial>
        <origin xyz=" 0.17830  0.00030 -0.00010"/>
        <mass value="1.8717"/>
        <inertia ixx="9.0E-4" iyy="0.0777" izz="0.0775" ixy="-0.0" ixz="-0.0" iyz="0.0"/>
    </inertial>
 <visual>
<origin xyz="0 0 0" rpy="0 0 0" />
	<geometry>
	<mesh filename="package://hyq_model/meshes/lower.dae" scale="1 1 1"/>
	</geometry>
      <material name="white"/>
    </visual>
<collision>
  <geometry>
    <mesh filename="package://hyq_model/meshes/lower_convex.dae" scale="0.001 0.001 0.001"/>
  </geometry>
</collision>
</link>


<link name="LH_hip_assembly">
    <inertial>
        <origin xyz=" 0.01310 -0.00010 -0.05730"/>
        <mass value="2.482"/>
        <inertia ixx="0.0956126" iyy="0.1012626" izz="6.758E-4" ixy="0.0" ixz="0.011" iyz="0.0"/>
    </inertial>
 <visual>
<origin xyz="0 0 0" rpy="3.141592654 0 0" />
	<geometry>
	<mesh filename="package://hyq_model/meshes/hip.dae" scale="1 1 1"/>
	</geometry>
      <material name="white"/>
    </visual>
<collision>
<origin xyz="0 0 0" rpy="0 1.5707964 0" />
  <geometry>
    <mesh filename="package://hyq_model/meshes/hip_convex.dae" scale="0.001 0.001 0.001"/>
  </geometry>
</collision>
</link>

<link name="LH_upper_leg">
    <inertial>
        <origin xyz=" 0.14796  0.02958  0.00000"/>
        <mass value="2.16"/>
        <inertia ixx="0.004785" iyy="0.076166" izz="0.078576" ixy="-0.0071588" ixz="0.0" iyz="0.0"/>
    </inertial>
 <visual> 
<origin xyz="0 0 0" rpy="3.141592654 0 0" />
	<geometry>
	<mesh filename="package://hyq_model/meshes/upper.dae" scale="1 1 1"/>
	</geometry>
      <material name="white"/>
    </visual>
<collision>
  <geometry>
    <mesh filename="package://hyq_model/meshes/upper_convex.dae" scale="0.001 0.001 0.001"/>
  </geometry>
</collision>
</link>

<link name="LH_lower_leg">
    <inertial>
        <origin xyz=" 0.17830  0.00030 -0.00010"/>
        <mass value="1.8717"/>
        <inertia ixx="9.0E-4" iyy="0.0777" izz="0.0775" ixy="-0.0" ixz="-0.0" iyz="0.0"/>
    </inertial>
 <visual>
<origin xyz="0 0 0" rpy="0 0 0" />
	<geometry>
	<mesh filename="package://hyq_model/meshes/lower.dae" scale="1 1 1"/>
	</geometry>
      <material name="white"/>
    </visual>
<collision>
  <geometry>
    <mesh filename="package://hyq_model/meshes/lower_convex.dae" scale="0.001 0.001 0.001"/>
  </geometry>
</collision>
</link>


<link name="RH_hip_assembly">
    <inertial>
        <origin xyz=" 0.01310  0.00010  0.05730"/>
        <mass value="2.482"/>
        <inertia ixx="0.0956126" iyy="0.1012626" izz="6.758E-4" ixy="0.0" ixz="-0.011" iyz="0.0"/>
    </inertial>
 <visual>
<origin xyz="0 0 0" rpy="0 0 0" />
	<geometry>
	<mesh filename="package://hyq_model/meshes/hip.dae" scale="1 1 1"/>
	</geometry>
      <material name="white"/>
    </visual>
<collision>
<origin xyz="0 0 0" rpy="3.141592654 -1.5707964 0" />
  <geometry>
    <mesh filename="package://hyq_model/meshes/hip_convex.dae" scale="0.001 0.001 0.001"/>
  </geometry>
</collision>
</link>

<link name="RH_upper_leg">
    <inertial>
        <origin xyz=" 0.14796 -0.02958  0.00000"/>
        <mass value="2.16"/>
        <inertia ixx="0.004785" iyy="0.076166" izz="0.078576" ixy="-0.0071588" ixz="0.0" iyz="0.0"/>
    </inertial>
 <visual> 
<origin xyz="0.00 0 0" rpy="3.141592654 0 0" />
	<geometry>
	<mesh filename="package://hyq_model/meshes/upper.dae" scale="1 1 1"/>
	</geometry>
      <material name="white"/>
    </visual>
<collision>
  <geometry>
    <mesh filename="package://hyq_model/meshes/upper_convex.dae" scale="0.001 0.001 0.001"/>
  </geometry>
</collision>
</link>

<link name="RH_lower_leg">
    <inertial>
        <origin xyz=" 0.17830  0.00030 -0.00010"/>
        <mass value="1.8717"/>
        <inertia ixx="9.0E-4" iyy="0.0777" izz="0.0775" ixy="0.0" ixz="0.0" iyz="0.0"/>
    </inertial>
 <visual>
<origin xyz="0.00 0 0" rpy="0 0 0" />
	<geometry>
	<mesh filename="package://hyq_model/meshes/lower.dae" scale="1 1 1"/>
	</geometry>
      <material name="white"/>
    </visual>
<collision>
  <geometry>
    <mesh filename="package://hyq_model/meshes/lower_convex.dae" scale="0.001 0.001 0.001"/>
  </geometry>
</collision>
</link>


<joint name="floating_base" type="fixed">
    <origin xyz=" 0.0  0.0  0.0" rpy="0.0 0.0 0.0"/>
    <parent link="base_link"/>
    <child  link="trunk"/>
</joint>

<joint name="LF_HAA" type="revolute">
    <origin xyz=" 0.37350  0.20700  0.00000" rpy="0.0 1.5707964 3.1415927"/>
    <parent link="trunk"/>
    <child  link="LF_hip_assembly"/>
    <limit effort="200.0" velocity="1000.0" lower="-1.5708" upper="0.5236"/>
    <axis xyz="0 0 1"/>
</joint>
<joint name="LF_HFE" type="revolute">
    <origin xyz=" 0.08000  0.00000  0.00000" rpy="1.5707964 0.0 0.0"/>
    <parent link="LF_hip_assembly"/>
    <child  link="LF_upper_leg"/>
    <limit effort="200.0" velocity="1.0" lower="-0.8727" upper="1.2217"/>
    <axis xyz="0 0 1"/>
</joint>
<joint name="LF_KFE" type="revolute">
    <origin xyz=" 0.35000  0.00000  0.00000" rpy="0.0 0.0 0.0"/>
    <parent link="LF_upper_leg"/>
    <child  link="LF_lower_leg"/>
    <limit effort="200.0" velocity="1.0" lower="-2.4435" upper="-0.3491"/>
    <axis xyz="0 0 1"/>
</joint>


<joint name="RF_HAA" type="revolute">
    <origin xyz=" 0.37350 -0.20700  0.00000" rpy="0.0 1.5707964 0.0"/>
    <parent link="trunk"/>
    <child  link="RF_hip_assembly"/>
    <limit effort="200.0" velocity="1.0" lower="-1.5708" upper="0.5236"/>
    <axis xyz="0 0 1"/>
</joint>
<joint name="RF_HFE" type="revolute">
    <origin xyz=" 0.08000  0.00000  0.00000" rpy="-1.5707964 0.0 0.0"/>
    <parent link="RF_hip_assembly"/>
    <child  link="RF_upper_leg"/>
    <limit effort="200.0" velocity="1.0"  lower="-0.8727" upper="1.2217"/>
    <axis xyz="0 0 1"/>
</joint>
<joint name="RF_KFE" type="revolute">
    <origin xyz=" 0.35000  0.00000  0.00000" rpy="0.0 0.0 0.0"/>
    <parent link="RF_upper_leg"/>
    <child  link="RF_lower_leg"/>
    <limit effort="200.0" velocity="1.0" lower="-2.4435" upper="-0.3491"/>
    <axis xyz="0 0 1"/>
</joint>


<joint name="LH_HAA" type="revolute">
    <origin xyz="-0.37350  0.20700  0.00000" rpy="0.0 1.5707964 3.1415927"/>
    <parent link="trunk"/>
    <child  link="LH_hip_assembly"/>
    <limit effort="200.0" velocity="1.0" lower="-1.5708" upper="0.5236"/>
    <axis xyz="0 0 1"/>
</joint>
<joint name="LH_HFE" type="revolute">
    <origin xyz=" 0.08000  0.00000  0.00000" rpy="1.5707964 0.0 0.0"/>
    <parent link="LH_hip_assembly"/>
    <child  link="LH_upper_leg"/>
    <limit effort="200.0" velocity="1.0" lower="-1.2217" upper="0.8727"/>
    <axis xyz="0 0 1"/>
</joint>
<joint name="LH_KFE" type="revolute">
    <origin xyz=" 0.35000  0.00000  0.00000" rpy="0.0 0.0 0.0"/>
    <parent link="LH_upper_leg"/>
    <child  link="LH_lower_leg"/>
    <limit effort="200.0" velocity="1.0" lower="0.3491" upper="2.4435"/>
    <axis xyz="0 0 1"/>
</joint>


<joint name="RH_HAA" type="revolute">
    <origin xyz="-0.37350 -0.20700  0.00000" rpy="0.0 1.5707964 0.0"/>
    <parent link="trunk"/>
    <child  link="RH_hip_assembly"/>
    <limit effort="200.0" velocity="1.0" lower="-1.5708" upper="0.5236"/>
    <axis xyz="0 0 1"/>
</joint>
<joint name="RH_HFE" type="revolute">
    <origin xyz=" 0.08000  0.00000  0.00000" rpy="-1.5707964 0.0 0.0"/>
    <parent link="RH_hip_assembly"/>
    <child  link="RH_upper_leg"/>
    <limit effort="200.0" velocity="1.0" lower="-1.2217" upper="0.8727"/>
    <axis xyz="0 0 1"/>
</joint>
<joint name="RH_KFE" type="revolute">
    <origin xyz=" 0.35000  0.00000  0.00000" rpy="0.0 0.0 0.0"/>
    <parent link="RH_upper_leg"/>
    <child  link="RH_lower_leg"/>
    <limit effort="200.0" velocity="1.0" lower="0.3491" upper="2.4435"/>
    <axis xyz="0 0 1"/>
</joint>

<joint name="velodyne_joint" type="fixed">
      <origin xyz="0.42 0 0.2" rpy="0 0 0" />
      <parent link="trunk" />
      <child link="velodyne"/>
</joint>

<link name="velodyne">
      <visual>
        <origin xyz="0 0 0" rpy="0 0 0"/>
        <geometry>
          <box size="0.05 0.05 0.10" />
        </geometry>
	<material name="gray">
            <color rgba=".5 .5 .5 1"/>
        </material>
      </visual>
</link>

<joint name="imu_joint" type="fixed">
      <origin xyz="0.3 0 0.1" rpy="0 0 0" />
      <parent link="trunk" />
      <child link="imu"/>
</joint>

<link name="imu">
      <visual>
        <origin xyz="0 0 0" rpy="0 0 0"/>
        <geometry>
          <box size="0.02 0.02 0.02" />
        </geometry>
      </visual>
</link>

<joint name="kinect" type="fixed">
      <origin xyz="0.7 0.04 0.02" rpy="0.0 1.2 0.0" /> 
      <parent link="trunk" />
      <child link="camera_link"/>
</joint>

<link name="camera_link">
      <visual>
        <origin xyz="0 0 0" rpy="0 0 0"/>
        <geometry>
          <box size="0.05 0.20 0.05" />
        </geometry>
	<material name="black">
            <color rgba=".13 .13 .13 1"/>
        </material>
      </visual>
</link>

<joint name="bumblebee" type="fixed">
      <origin xyz="0.75 -0.01 0.03" rpy="-2.8 0.0 -1.57" />
      <parent link="trunk" />
      <child link="bumblebee_link"/>
</joint>

<link name="bumblebee_link">
      <visual>
        <origin xyz="0 0 0" rpy="0 0 0"/>
        <geometry>
          <box size="0.15 0.05 0.05" />
        </geometry>
	<material name="yellow">
            <color rgba=".55 .55 0.15 1"/>
        </material>
      </visual>
</link>

</robot>
